<?xml version="1.0" encoding="UTF-8"?>
<robot name="ur5e_wr_gripper_4">
  <joint name="elbow_joint" type="revolute">
    <origin xyz="-0.425 0. 0. " rpy="0. 0. 0."/>
    <parent link="upper_arm_link"/>
    <child link="forearm_link"/>
    <axis xyz="0. 0. 1."/>
    <limit lower="-3.1415927" upper="3.1415927" effort="150." velocity="3.1415927"/>
  </joint>
  <joint name="finger_1_joint" type="prismatic">
    <origin xyz="0.0714 -0.0185 0.04525" rpy="0. 0. -1.5707964"/>
    <parent link="gripper_wr"/>
    <child link="wr_finger_right"/>
    <axis xyz="0. 0. 1."/>
    <limit lower="0." upper="0.043" effort="7.1999998" velocity="0.1"/>
  </joint>
  <joint name="finger_2_joint" type="prismatic">
    <origin xyz="0.0714 0.0185 -0.04525" rpy="3.1415927 -0. 1.5707964"/>
    <parent link="gripper_wr"/>
    <child link="wr_finger_left"/>
    <axis xyz="0. 0. 1."/>
    <limit lower="0." upper="0.043" effort="7.1999998" velocity="0.1"/>
  </joint>
  <joint name="joint_gripper_wr-Camera" type="fixed">
    <origin xyz="0. 0. 0." rpy="-0. 0. 3.1415927"/>
    <parent link="gripper_wr"/>
    <child link="Camera"/>
  </joint>
  <joint name="robot_gripper_joint" type="fixed">
    <origin xyz="-0. -0. -0.0000001" rpy="-1.5707963 -1.5707964 0. "/>
    <parent link="wrist_3_link"/>
    <child link="gripper_wr"/>
  </joint>
  <joint name="root_joint" type="fixed">
    <origin xyz="0. 0. 0." rpy="0. 0. 0."/>
    <parent link="World"/>
    <child link="ur5e_base_link"/>
  </joint>
  <joint name="shoulder_lift_joint" type="revolute">
    <origin xyz="0. 0. 0." rpy="1.5707964 0. 0. "/>
    <parent link="shoulder_link"/>
    <child link="upper_arm_link"/>
    <axis xyz="0. 0. 1."/>
    <limit lower="-6.2831853" upper="6.2831853" effort="150." velocity="3.1415927"/>
  </joint>
  <joint name="shoulder_pan_joint" type="revolute">
    <origin xyz="0. 0. 0.1625" rpy="0. 0. -3.1415925"/>
    <parent link="ur5e_base_link"/>
    <child link="shoulder_link"/>
    <axis xyz="0. 0. 1."/>
    <limit lower="-6.2831853" upper="6.2831853" effort="150." velocity="3.1415927"/>
  </joint>
  <joint name="wrist_1_joint" type="revolute">
    <origin xyz="-0.3922 0. 0.1333" rpy="0. 0. 0."/>
    <parent link="forearm_link"/>
    <child link="wrist_1_link"/>
    <axis xyz="0. 0. 1."/>
    <limit lower="-6.2831853" upper="6.2831853" effort="28." velocity="3.1415927"/>
  </joint>
  <joint name="wrist_2_joint" type="revolute">
    <origin xyz="-0. -0.0997 -0. " rpy="1.5707964 0. 0. "/>
    <parent link="wrist_1_link"/>
    <child link="wrist_2_link"/>
    <axis xyz="0. 0. 1."/>
    <limit lower="-6.2831853" upper="6.2831853" effort="28." velocity="3.1415927"/>
  </joint>
  <joint name="wrist_3_joint" type="revolute">
    <origin xyz="0. 0.0996 -0. " rpy="-1.5707964 -0.0000001 0.0000001"/>
    <parent link="wrist_2_link"/>
    <child link="wrist_3_link"/>
    <axis xyz="0. 0. 1."/>
    <limit lower="-6.2831853" upper="6.2831853" effort="28." velocity="3.1415927"/>
  </joint>
  <link name="Camera"/>
  <link name="World"/>
  <link name="forearm_link">
    <inertial>
      <origin xyz="-0.1961 0. 0.007 " rpy="0. 0. 0."/>
      <mass value="2.2750001"/>
      <inertia ixx="0.004095" ixy="0." ixz="0." iyy="0.0312094" iyz="0." izz="0.0312094"/>
    </inertial>
    <visual>
      <origin xyz="0. 0. 0.007" rpy="3.1415837 0. -1.5707964"/>
      <geometry>
        <mesh filename="file:///home/AP_DeepPoint/work/Deep-Point/urdf/meshes/forearm_link_visuals_forearm_mesh.obj" scale="1. 1. 1."/>
      </geometry>
    </visual>
    <visual>
      <origin xyz="0. 0. 0.007" rpy="1.5707964 0. -1.5707964"/>
      <geometry>
        <mesh filename="file:///home/AP_DeepPoint/work/Deep-Point/urdf/meshes/forearm_link_collisions_forearm_mesh.obj" scale="1. 1. 1."/>
      </geometry>
    </visual>
    <collision>
      <origin xyz="0. 0. 0.007" rpy="1.5707964 0. -1.5707964"/>
      <geometry>
        <mesh filename="file:///home/AP_DeepPoint/work/Deep-Point/urdf/meshes/forearm_link_collisions_forearm_mesh.obj" scale="1. 1. 1."/>
      </geometry>
    </collision>
  </link>
  <link name="gripper_wr">
    <inertial>
      <origin xyz="0.0435194 -0. -0.0000134" rpy="0. 0. 0."/>
      <mass value="0.9945512"/>
      <inertia ixx="0.0011937" ixy="-0." ixz="0." iyy="0.0011891" iyz="0." izz="0.0005804"/>
    </inertial>
    <visual>
      <origin xyz="0.004 0. 0. " rpy="0. 1.5707963 0. "/>
      <geometry>
        <mesh filename="file:///home/AP_DeepPoint/work/Deep-Point/urdf/meshes/gripper_wr_FL_ISO50_CRG200_Grundkorper_CUSTOMER_FL_ISO50_CRG200_Grundkorper_CUSTOMER_FL_ISO50_CRG200_Grundkorper_CUSTOMER_FL_ISO50_CRG200_Grundkorper_CUSTOMER.obj" scale="1. 1. 1."/>
      </geometry>
    </visual>
    <visual>
      <origin xyz="0.004 0. 0. " rpy="3.1415927 -1.5707963 0. "/>
      <geometry>
        <mesh filename="file:///home/AP_DeepPoint/work/Deep-Point/urdf/meshes/gripper_wr_FL_ISO50_CRG200_Grundkorper_CUSTOMER_KamerahalterungNeu_KamerahalterungNeu.obj" scale="1. 1. 1."/>
      </geometry>
    </visual>
    <visual>
      <origin xyz="0.0714 0. 0. " rpy="3.1415927 -1.5707963 0. "/>
      <geometry>
        <mesh filename="file:///home/AP_DeepPoint/work/Deep-Point/urdf/meshes/gripper_wr_FL_ISO50_CRG200_Grundkorper_CUSTOMER_CRG200_top_cover_CRG200_top_cover.obj" scale="1. 1. 1."/>
      </geometry>
    </visual>
    <visual>
      <origin xyz="0.0138 0. 0. " rpy="3.1415927 -1.5707963 0. "/>
      <geometry>
        <mesh filename="file:///home/AP_DeepPoint/work/Deep-Point/urdf/meshes/gripper_wr_FL_ISO50_CRG200_Grundkorper_CUSTOMER_CRG200_body_CRG200_body_CRG200_body.obj" scale="1. 1. 1."/>
      </geometry>
    </visual>
    <collision>
      <origin xyz="0.004 0. 0. " rpy="0. 1.5707963 0. "/>
      <geometry>
        <mesh filename="file:///home/AP_DeepPoint/work/Deep-Point/urdf/meshes/gripper_wr_FL_ISO50_CRG200_Grundkorper_CUSTOMER_FL_ISO50_CRG200_Grundkorper_CUSTOMER_FL_ISO50_CRG200_Grundkorper_CUSTOMER_FL_ISO50_CRG200_Grundkorper_CUSTOMER.obj" scale="1. 1. 1."/>
      </geometry>
    </collision>
    <collision>
      <origin xyz="0.004 0. 0. " rpy="3.1415927 -1.5707963 0. "/>
      <geometry>
        <mesh filename="file:///home/AP_DeepPoint/work/Deep-Point/urdf/meshes/gripper_wr_FL_ISO50_CRG200_Grundkorper_CUSTOMER_KamerahalterungNeu_KamerahalterungNeu.obj" scale="1. 1. 1."/>
      </geometry>
    </collision>
    <collision>
      <origin xyz="0.0714 0. 0. " rpy="3.1415927 -1.5707963 0. "/>
      <geometry>
        <mesh filename="file:///home/AP_DeepPoint/work/Deep-Point/urdf/meshes/gripper_wr_FL_ISO50_CRG200_Grundkorper_CUSTOMER_CRG200_top_cover_CRG200_top_cover.obj" scale="1. 1. 1."/>
      </geometry>
    </collision>
    <collision>
      <origin xyz="0.0138 0. 0. " rpy="3.1415927 -1.5707963 0. "/>
      <geometry>
        <mesh filename="file:///home/AP_DeepPoint/work/Deep-Point/urdf/meshes/gripper_wr_FL_ISO50_CRG200_Grundkorper_CUSTOMER_CRG200_body_CRG200_body_CRG200_body.obj" scale="1. 1. 1."/>
      </geometry>
    </collision>
  </link>
  <link name="shoulder_link">
    <inertial>
      <origin xyz="0. 0. 0." rpy="0. 0. 0."/>
      <mass value="3.7"/>
      <inertia ixx="0.0102675" ixy="0." ixz="0." iyy="0.0102675" iyz="0." izz="0.00666"/>
    </inertial>
    <visual>
      <origin xyz="0. 0. 0." rpy="1.5707872 0. -3.1415925"/>
      <geometry>
        <mesh filename="file:///home/AP_DeepPoint/work/Deep-Point/urdf/meshes/shoulder_link_visuals_shoulder_mesh.obj" scale="1. 1. 1."/>
      </geometry>
    </visual>
    <visual>
      <origin xyz="0. 0. 0." rpy="0. 0. -3.1415925"/>
      <geometry>
        <mesh filename="file:///home/AP_DeepPoint/work/Deep-Point/urdf/meshes/shoulder_link_collisions_shoulder_mesh.obj" scale="1. 1. 1."/>
      </geometry>
    </visual>
    <collision>
      <origin xyz="0. 0. 0." rpy="0. 0. -3.1415925"/>
      <geometry>
        <mesh filename="file:///home/AP_DeepPoint/work/Deep-Point/urdf/meshes/shoulder_link_collisions_shoulder_mesh.obj" scale="1. 1. 1."/>
      </geometry>
    </collision>
  </link>
  <link name="upper_arm_link">
    <inertial>
      <origin xyz="-0.2125 0. 0.138 " rpy="0. 0. 0."/>
      <mass value="8.3929996"/>
      <inertia ixx="0.0151074" ixy="0." ixz="0." iyy="0.1338858" iyz="0." izz="0.1338858"/>
    </inertial>
    <visual>
      <origin xyz="0. 0. 0.138" rpy="3.1415837 0. -1.5707964"/>
      <geometry>
        <mesh filename="file:///home/AP_DeepPoint/work/Deep-Point/urdf/meshes/upper_arm_link_visuals_upperarm_mesh.obj" scale="1. 1. 1."/>
      </geometry>
    </visual>
    <visual>
      <origin xyz="0. 0. 0.138" rpy="1.5707964 0. -1.5707964"/>
      <geometry>
        <mesh filename="file:///home/AP_DeepPoint/work/Deep-Point/urdf/meshes/upper_arm_link_collisions_upperarm_mesh.obj" scale="1. 1. 1."/>
      </geometry>
    </visual>
    <collision>
      <origin xyz="0. 0. 0.138" rpy="1.5707964 0. -1.5707964"/>
      <geometry>
        <mesh filename="file:///home/AP_DeepPoint/work/Deep-Point/urdf/meshes/upper_arm_link_collisions_upperarm_mesh.obj" scale="1. 1. 1."/>
      </geometry>
    </collision>
  </link>
  <link name="ur5e_base_link">
    <inertial>
      <origin xyz="0. 0. 0." rpy="0. 0. 0."/>
      <mass value="4."/>
      <inertia ixx="0.0044333" ixy="0." ixz="0." iyy="0.0044333" iyz="0." izz="0.0072"/>
    </inertial>
    <visual>
      <origin xyz="0. 0. 0." rpy="1.5707872 0. 0. "/>
      <geometry>
        <mesh filename="file:///home/AP_DeepPoint/work/Deep-Point/urdf/meshes/ur5e_base_link_visuals_base_mesh.obj" scale="1. 1. 1."/>
      </geometry>
    </visual>
    <visual>
      <origin xyz="0. 0. 0." rpy="0. 0. 0."/>
      <geometry>
        <mesh filename="file:///home/AP_DeepPoint/work/Deep-Point/urdf/meshes/ur5e_base_link_collisions_base_mesh.obj" scale="1. 1. 1."/>
      </geometry>
    </visual>
    <collision>
      <origin xyz="0. 0. 0." rpy="0. 0. 0."/>
      <geometry>
        <mesh filename="file:///home/AP_DeepPoint/work/Deep-Point/urdf/meshes/ur5e_base_link_collisions_base_mesh.obj" scale="1. 1. 1."/>
      </geometry>
    </collision>
  </link>
  <link name="wr_finger_left">
    <inertial>
      <origin xyz="-0. 0.0048968 -0.0228834" rpy="0. 0. 0."/>
      <mass value="0.0099532"/>
      <inertia ixx="0.0000017" ixy="-0." ixz="0." iyy="0.0000018" iyz="-0." izz="0.0000002"/>
    </inertial>
    <visual>
      <origin xyz="-0. 0.0124 -0.016 " rpy="-1.5707964 -1.5707964 0. "/>
      <geometry>
        <mesh filename="file:///home/AP_DeepPoint/work/Deep-Point/urdf/meshes/wr_finger_left_CRG200_base_jaw_Greifensatz_Greifensatz.obj" scale="1. 1. 1."/>
      </geometry>
    </visual>
    <visual>
      <origin xyz="-0. -0. -0.027" rpy="-1.5707964 -1.5707964 0. "/>
      <geometry>
        <mesh filename="file:///home/AP_DeepPoint/work/Deep-Point/urdf/meshes/wr_finger_left_CRG200_base_jaw_CRG200_base_jaw_CRG200_base_jaw.obj" scale="1. 1. 1."/>
      </geometry>
    </visual>
    <collision>
      <origin xyz="-0. 0.0124 -0.016 " rpy="-1.5707964 -1.5707964 0. "/>
      <geometry>
        <mesh filename="file:///home/AP_DeepPoint/work/Deep-Point/urdf/meshes/wr_finger_left_CRG200_base_jaw_Greifensatz_Greifensatz.obj" scale="1. 1. 1."/>
      </geometry>
    </collision>
    <collision>
      <origin xyz="-0. -0. -0.027" rpy="-1.5707964 -1.5707964 0. "/>
      <geometry>
        <mesh filename="file:///home/AP_DeepPoint/work/Deep-Point/urdf/meshes/wr_finger_left_CRG200_base_jaw_CRG200_base_jaw_CRG200_base_jaw.obj" scale="1. 1. 1."/>
      </geometry>
    </collision>
  </link>
  <link name="wr_finger_right">
    <inertial>
      <origin xyz="-0.0125647 0.0294718 -0.0023601" rpy="0. 0. 0."/>
      <mass value="0.0145158"/>
      <inertia ixx="0.0000042" ixy="0." ixz="0." iyy="0.0000047" iyz="-0." izz="0.0000014"/>
    </inertial>
    <visual>
      <origin xyz="0. -0. -0.027" rpy="-1.5707964 -1.5707964 0. "/>
      <geometry>
        <mesh filename="file:///home/AP_DeepPoint/work/Deep-Point/urdf/meshes/wr_finger_right_CRG200_base_jaw_CRG200_base_jaw_CRG200_base_jaw.obj" scale="1. 1. 1."/>
      </geometry>
    </visual>
    <visual>
      <origin xyz="0. 0.0124 -0.016 " rpy="-1.5707964 -1.5707964 0. "/>
      <geometry>
        <mesh filename="file:///home/AP_DeepPoint/work/Deep-Point/urdf/meshes/wr_finger_right_CRG200_base_jaw_Greifensatz_Greifensatz.obj" scale="1. 1. 1."/>
      </geometry>
    </visual>
    <collision>
      <origin xyz="0. -0. -0.027" rpy="-1.5707964 -1.5707964 0. "/>
      <geometry>
        <mesh filename="file:///home/AP_DeepPoint/work/Deep-Point/urdf/meshes/wr_finger_right_CRG200_base_jaw_CRG200_base_jaw_CRG200_base_jaw.obj" scale="1. 1. 1."/>
      </geometry>
    </collision>
    <collision>
      <origin xyz="0. 0.0124 -0.016 " rpy="-1.5707964 -1.5707964 0. "/>
      <geometry>
        <mesh filename="file:///home/AP_DeepPoint/work/Deep-Point/urdf/meshes/wr_finger_right_CRG200_base_jaw_Greifensatz_Greifensatz.obj" scale="1. 1. 1."/>
      </geometry>
    </collision>
  </link>
  <link name="wrist_1_link">
    <inertial>
      <origin xyz="0. 0. 0." rpy="0. 0. 0."/>
      <mass value="1.219"/>
      <inertia ixx="0.0025599" ixy="0." ixz="0." iyy="0.0025599" iyz="0." izz="0.0021942"/>
    </inertial>
    <visual>
      <origin xyz="-0. 0. -0.127" rpy="3.1415837 0. 0. "/>
      <geometry>
        <mesh filename="file:///home/AP_DeepPoint/work/Deep-Point/urdf/meshes/wrist_1_link_visuals_wrist1_mesh.obj" scale="1. 1. 1."/>
      </geometry>
    </visual>
    <visual>
      <origin xyz="-0. 0. -0.127" rpy="1.5707964 0. 0. "/>
      <geometry>
        <mesh filename="file:///home/AP_DeepPoint/work/Deep-Point/urdf/meshes/wrist_1_link_collisions_wrist1_mesh.obj" scale="1. 1. 1."/>
      </geometry>
    </visual>
    <collision>
      <origin xyz="-0. 0. -0.127" rpy="1.5707964 0. 0. "/>
      <geometry>
        <mesh filename="file:///home/AP_DeepPoint/work/Deep-Point/urdf/meshes/wrist_1_link_collisions_wrist1_mesh.obj" scale="1. 1. 1."/>
      </geometry>
    </collision>
  </link>
  <link name="wrist_2_link">
    <inertial>
      <origin xyz="0. 0. 0." rpy="0. 0. 0."/>
      <mass value="1.219"/>
      <inertia ixx="0.0025599" ixy="0." ixz="0." iyy="0.0025599" iyz="0." izz="0.0021942"/>
    </inertial>
    <visual>
      <origin xyz="0. 0. -0.0997" rpy="1.5707872 0. 0. "/>
      <geometry>
        <mesh filename="file:///home/AP_DeepPoint/work/Deep-Point/urdf/meshes/wrist_2_link_visuals_wrist2_mesh.obj" scale="1. 1. 1."/>
      </geometry>
    </visual>
    <visual>
      <origin xyz="0. 0. -0.0997" rpy="0. 0. 0."/>
      <geometry>
        <mesh filename="file:///home/AP_DeepPoint/work/Deep-Point/urdf/meshes/wrist_2_link_collisions_wrist2_mesh.obj" scale="1. 1. 1."/>
      </geometry>
    </visual>
    <collision>
      <origin xyz="0. 0. -0.0997" rpy="0. 0. 0."/>
      <geometry>
        <mesh filename="file:///home/AP_DeepPoint/work/Deep-Point/urdf/meshes/wrist_2_link_collisions_wrist2_mesh.obj" scale="1. 1. 1."/>
      </geometry>
    </collision>
  </link>
  <link name="wrist_3_link">
    <inertial>
      <origin xyz="0. 0. -0.0229" rpy="0. 0. 0."/>
      <mass value="0.1879"/>
      <inertia ixx="0.0000989" ixy="0." ixz="0." iyy="0.0000989" iyz="0." izz="0.0001321"/>
    </inertial>
    <visual>
      <origin xyz="-0. -0. -0.0989" rpy="3.1415837 0. 0. "/>
      <geometry>
        <mesh filename="file:///home/AP_DeepPoint/work/Deep-Point/urdf/meshes/wrist_3_link_visuals_wrist3_mesh.obj" scale="1. 1. 1."/>
      </geometry>
    </visual>
    <visual>
      <origin xyz="-0. -0. -0.0989" rpy="1.5707964 0. 0. "/>
      <geometry>
        <mesh filename="file:///home/AP_DeepPoint/work/Deep-Point/urdf/meshes/wrist_3_link_collisions_wrist3_mesh.obj" scale="1. 1. 1."/>
      </geometry>
    </visual>
    <collision>
      <origin xyz="-0. -0. -0.0989" rpy="1.5707964 0. 0. "/>
      <geometry>
        <mesh filename="file:///home/AP_DeepPoint/work/Deep-Point/urdf/meshes/wrist_3_link_collisions_wrist3_mesh.obj" scale="1. 1. 1."/>
      </geometry>
    </collision>
  </link>
</robot>
